Traceback (most recent call last):
  File "/home/felix/miniconda3/lib/python3.9/site-packages/jupyter_cache/executors/utils.py", line 51, in single_nb_execution
    executenb(
  File "/home/felix/miniconda3/lib/python3.9/site-packages/nbclient/client.py", line 1112, in execute
    return NotebookClient(nb=nb, resources=resources, km=km, **kwargs).execute()
  File "/home/felix/miniconda3/lib/python3.9/site-packages/nbclient/util.py", line 74, in wrapped
    return just_run(coro(*args, **kwargs))
  File "/home/felix/miniconda3/lib/python3.9/site-packages/nbclient/util.py", line 53, in just_run
    return loop.run_until_complete(coro)
  File "/home/felix/miniconda3/lib/python3.9/asyncio/base_events.py", line 642, in run_until_complete
    return future.result()
  File "/home/felix/miniconda3/lib/python3.9/site-packages/nbclient/client.py", line 553, in async_execute
    await self.async_execute_cell(
  File "/home/felix/miniconda3/lib/python3.9/site-packages/nbclient/client.py", line 857, in async_execute_cell
    self._check_raise_for_error(cell, exec_reply)
  File "/home/felix/miniconda3/lib/python3.9/site-packages/nbclient/client.py", line 760, in _check_raise_for_error
    raise CellExecutionError.from_cell_and_msg(cell, exec_reply_content)
nbclient.exceptions.CellExecutionError: An error occurred while executing the following cell:
------------------
#2. Inversa de una matriz
linalg.inv(arr)
# calcular la inversa de una matriz singular (su determinante es cero) generar√° un error
------------------

[0;31m---------------------------------------------------------------------------[0m
[0;31mLinAlgError[0m                               Traceback (most recent call last)
[0;32m<ipython-input-3-317de499420c>[0m in [0;36m<module>[0;34m[0m
[1;32m      1[0m [0;31m#2. Inversa de una matriz[0m[0;34m[0m[0;34m[0m[0;34m[0m[0m
[0;32m----> 2[0;31m [0mlinalg[0m[0;34m.[0m[0minv[0m[0;34m([0m[0marr[0m[0;34m)[0m[0;34m[0m[0;34m[0m[0m
[0m[1;32m      3[0m [0;31m# calcular la inversa de una matriz singular (su determinante es cero) generar√° un error[0m[0;34m[0m[0;34m[0m[0;34m[0m[0m

[0;32m~/miniconda3/lib/python3.9/site-packages/scipy/linalg/basic.py[0m in [0;36minv[0;34m(a, overwrite_a, check_finite)[0m
[1;32m    966[0m         [0minv_a[0m[0;34m,[0m [0minfo[0m [0;34m=[0m [0mgetri[0m[0;34m([0m[0mlu[0m[0;34m,[0m [0mpiv[0m[0;34m,[0m [0mlwork[0m[0;34m=[0m[0mlwork[0m[0;34m,[0m [0moverwrite_lu[0m[0;34m=[0m[0;36m1[0m[0;34m)[0m[0;34m[0m[0;34m[0m[0m
[1;32m    967[0m     [0;32mif[0m [0minfo[0m [0;34m>[0m [0;36m0[0m[0;34m:[0m[0;34m[0m[0;34m[0m[0m
[0;32m--> 968[0;31m         [0;32mraise[0m [0mLinAlgError[0m[0;34m([0m[0;34m"singular matrix"[0m[0;34m)[0m[0;34m[0m[0;34m[0m[0m
[0m[1;32m    969[0m     [0;32mif[0m [0minfo[0m [0;34m<[0m [0;36m0[0m[0;34m:[0m[0;34m[0m[0;34m[0m[0m
[1;32m    970[0m         raise ValueError('illegal value in %d-th argument of internal '

[0;31mLinAlgError[0m: singular matrix
LinAlgError: singular matrix

